<?xml version="1.0"?>
<robot name="Egg_Handler">

    <link name="palm_link">
        <visual>
            <geometry>
                <cylinder radius="0.0200" length="0.0100"/>
            </geometry>
        </visual>
        <collision>
            <geometry>
                <cylinder radius="0.0200" length="0.0100"/>
            </geometry>
        </collision>
    </link>

    
    <link name="finger_0_link">
        <visual>
            <geometry>
                <cylinder radius="0.0045" length="0.0600"/>
            </geometry>
            <origin xyz="0 0 0.0300"/>
        </visual>
        <collision>
            <geometry>
                <cylinder radius="0.0045" length="0.0600"/>
            </geometry>
            <origin xyz="0 0 0.0300"/>
        </collision>
    </link>

    <joint name="finger_0_joint" type="revolute">
        <parent link="palm_link"/>
        <child link="finger_0_link"/>
        <origin xyz="0.0200 0.0000 0.0100" rpy="0 0 0.0000"/>
        <axis xyz="0 1 0"/>
        <limit lower="-1.57" upper="1.57" effort="10" velocity="1"/>
    </joint>

    <link name="finger_1_link">
        <visual>
            <geometry>
                <cylinder radius="0.0045" length="0.0600"/>
            </geometry>
            <origin xyz="0 0 0.0300"/>
        </visual>
        <collision>
            <geometry>
                <cylinder radius="0.0045" length="0.0600"/>
            </geometry>
            <origin xyz="0 0 0.0300"/>
        </collision>
    </link>

    <joint name="finger_1_joint" type="revolute">
        <parent link="palm_link"/>
        <child link="finger_1_link"/>
        <origin xyz="0.0000 0.0200 0.0100" rpy="0 0 1.5708"/>
        <axis xyz="0 1 0"/>
        <limit lower="-1.57" upper="1.57" effort="10" velocity="1"/>
    </joint>

    <link name="finger_2_link">
        <visual>
            <geometry>
                <cylinder radius="0.0045" length="0.0600"/>
            </geometry>
            <origin xyz="0 0 0.0300"/>
        </visual>
        <collision>
            <geometry>
                <cylinder radius="0.0045" length="0.0600"/>
            </geometry>
            <origin xyz="0 0 0.0300"/>
        </collision>
    </link>

    <joint name="finger_2_joint" type="revolute">
        <parent link="palm_link"/>
        <child link="finger_2_link"/>
        <origin xyz="-0.0200 0.0000 0.0100" rpy="0 0 3.1416"/>
        <axis xyz="0 1 0"/>
        <limit lower="-1.57" upper="1.57" effort="10" velocity="1"/>
    </joint>

    <link name="finger_3_link">
        <visual>
            <geometry>
                <cylinder radius="0.0045" length="0.0600"/>
            </geometry>
            <origin xyz="0 0 0.0300"/>
        </visual>
        <collision>
            <geometry>
                <cylinder radius="0.0045" length="0.0600"/>
            </geometry>
            <origin xyz="0 0 0.0300"/>
        </collision>
    </link>

    <joint name="finger_3_joint" type="revolute">
        <parent link="palm_link"/>
        <child link="finger_3_link"/>
        <origin xyz="-0.0000 -0.0200 0.0100" rpy="0 0 4.7124"/>
        <axis xyz="0 1 0"/>
        <limit lower="-1.57" upper="1.57" effort="10" velocity="1"/>
    </joint>

</robot>
