<?xml version="1.0" encoding="utf-8"?>
<mujoco model="composed_scene">
  <compiler angle="radian" autolimits="true"/>
  <option timestep="0.002" gravity="0 0 -9.81"/>
  <worldbody>
    <geom name="ground" type="plane" size="1 1 0.1" condim="3"/>
    <light name="main" pos="0.5 0.5 1.2" dir="0 0 -1" directional="true"/>
    <camera name="main" pos="0.800 0.600 0.500" fovy="60" mode="fixed"/>
    <body name="surface_table" pos="0.0000 0.0000 0.0000"><geom name="table_geom" type="box" size="0.4 0.3 0.02" pos="0 0 0.02" rgba="0.5 0.45 0.4 1" condim="3"/></body>
    <body name="gripper_test_gripper_base" pos="0.0000 0.0000 0.1200">
      <joint name="gripper_test_gripper_x" type="slide" axis="1 0 0" range="-0.2 0.2"/>
      <joint name="gripper_test_gripper_y" type="slide" axis="0 1 0" range="-0.2 0.2"/>
      <joint name="gripper_test_gripper_z" type="slide" axis="0 0 1" range="-0.1 0.3"/>
      <body name="gripper_test_gripper" pos="0.0000 0.0000 0.0000">
            <geom class="palm" name="palm_geom" size="0.0105 0.0050" pos="0 0 0.0050" />
            <body name="finger_0_base" pos="0.0068 0.0000 0.0100">
              <joint class="gripper" name="finger_0_base_joint" axis="0 1 0" stiffness="0.0200" damping="0.1500" />
              <site name="finger_0_site_0" pos="0 0 0.002" size="0.002" />
              <geom class="gripper" name="finger_0_seg_0" fromto="0 0 0.0020 0 0 0.0075" size="0.0028" />
              <body name="finger_0_seg_1" pos="0 0 0.0075">
                <joint class="gripper" name="finger_0_joint_1" axis="0 1 0" stiffness="0.0170" damping="0.1200" />
                <geom class="gripper" name="finger_0_seg_1_geom" fromto="0 0 0.001 0 0 0.0075" size="0.0026" />
                <site name="finger_0_site_1" pos="0 0 0.0037" size="0.002" />
              </body>
              <body name="finger_0_seg_2" pos="0 0 0.0075">
                <joint class="gripper" name="finger_0_joint_2" axis="0 1 0" stiffness="0.0140" damping="0.0900" />
                <geom class="gripper" name="finger_0_seg_2_geom" fromto="0 0 0.001 0 0 0.0075" size="0.0023" />
                <site name="finger_0_site_2" pos="0 0 0.0037" size="0.002" />
              </body>
              <body name="finger_0_seg_3" pos="0 0 0.0075">
                <joint class="gripper" name="finger_0_joint_3" axis="0 1 0" stiffness="0.0110" damping="0.0750" />
                <geom class="gripper" name="finger_0_seg_3_geom" fromto="0 0 0.001 0 0 0.0075" size="0.0020" />
                <site name="finger_0_site_3" pos="0 0 0.0037" size="0.002" />
              </body>
            </body>
            <body name="finger_1_base" pos="-0.0068 0.0000 0.0100">
              <joint class="gripper" name="finger_1_base_joint" axis="0 1 0" stiffness="0.0200" damping="0.1500" />
              <site name="finger_1_site_0" pos="0 0 0.002" size="0.002" />
              <geom class="gripper" name="finger_1_seg_0" fromto="0 0 0.0020 0 0 0.0075" size="0.0028" />
              <body name="finger_1_seg_1" pos="0 0 0.0075">
                <joint class="gripper" name="finger_1_joint_1" axis="0 1 0" stiffness="0.0170" damping="0.1200" />
                <geom class="gripper" name="finger_1_seg_1_geom" fromto="0 0 0.001 0 0 0.0075" size="0.0026" />
                <site name="finger_1_site_1" pos="0 0 0.0037" size="0.002" />
              </body>
              <body name="finger_1_seg_2" pos="0 0 0.0075">
                <joint class="gripper" name="finger_1_joint_2" axis="0 1 0" stiffness="0.0140" damping="0.0900" />
                <geom class="gripper" name="finger_1_seg_2_geom" fromto="0 0 0.001 0 0 0.0075" size="0.0023" />
                <site name="finger_1_site_2" pos="0 0 0.0037" size="0.002" />
              </body>
              <body name="finger_1_seg_3" pos="0 0 0.0075">
                <joint class="gripper" name="finger_1_joint_3" axis="0 1 0" stiffness="0.0110" damping="0.0750" />
                <geom class="gripper" name="finger_1_seg_3_geom" fromto="0 0 0.001 0 0 0.0075" size="0.0020" />
                <site name="finger_1_site_3" pos="0 0 0.0037" size="0.002" />
              </body>
            </body>
          </body>
    </body>
    <body name="object_egg" pos="0.0000 0.0000 0.0600"><freejoint name="egg_joint"/><geom name="egg_geom" type="ellipsoid" size="0.02 0.025 0.03" mass="0.100" rgba="0.95 0.95 0.9 1"/></body>
  </worldbody>
  <default>
    <default class="gripper">
    <geom type="capsule" condim="4" friction="0.9 0.005 0.0001" rgba="0.9 0.85 0.8 1" margin="0.001" />
    <joint type="hinge" limited="true" range="-1.57 1.57" stiffness="0.02" damping="0.15" armature="0.001" />
    </default>
    <default class="palm"><geom type="cylinder" rgba="0.4 0.4 0.5 1" friction="0.9 0.005 0.0001" />
    </default>
  </default>
  <tendon>
    <spatial name="finger_0_flexor" limited="true" range="0 0.15" width="0.002" frictionloss="0.1">
    <site site="finger_0_site_0" />
    <site site="finger_0_site_1" />
    <site site="finger_0_site_2" />
    <site site="finger_0_site_3" />
    </spatial>
    <spatial name="finger_0_extensor" limited="true" range="0 0.15" width="0.002" frictionloss="0.1">
    <site site="finger_0_site_3" />
    <site site="finger_0_site_2" />
    <site site="finger_0_site_1" />
    <site site="finger_0_site_0" />
    </spatial>
    <spatial name="finger_1_flexor" limited="true" range="0 0.15" width="0.002" frictionloss="0.1">
    <site site="finger_1_site_0" />
    <site site="finger_1_site_1" />
    <site site="finger_1_site_2" />
    <site site="finger_1_site_3" />
    </spatial>
    <spatial name="finger_1_extensor" limited="true" range="0 0.15" width="0.002" frictionloss="0.1">
    <site site="finger_1_site_3" />
    <site site="finger_1_site_2" />
    <site site="finger_1_site_1" />
    <site site="finger_1_site_0" />
    </spatial>
  </tendon>
  <actuator>
    <position name="gripper_test_gripper_x_act" joint="gripper_test_gripper_x" kp="100"/>
    <position name="gripper_test_gripper_y_act" joint="gripper_test_gripper_y" kp="100"/>
    <position name="gripper_test_gripper_z_act" joint="gripper_test_gripper_z" kp="100"/>
    <motor name="finger_0_flexor_motor" tendon="finger_0_flexor" gear="12" ctrllimited="true" ctrlrange="0 1" />
    <motor name="finger_0_extensor_motor" tendon="finger_0_extensor" gear="6" ctrllimited="true" ctrlrange="0 0.5" />
    <motor name="finger_1_flexor_motor" tendon="finger_1_flexor" gear="12" ctrllimited="true" ctrlrange="0 1" />
    <motor name="finger_1_extensor_motor" tendon="finger_1_extensor" gear="6" ctrllimited="true" ctrlrange="0 0.5" />
  </actuator>
  <sensor>
    <jointpos name="finger_0_pos" joint="finger_0_base_joint" />
    <jointvel name="finger_0_vel" joint="finger_0_base_joint" />
    <tendonpos name="finger_0_flexor_len" tendon="finger_0_flexor" />
    <jointpos name="finger_1_pos" joint="finger_1_base_joint" />
    <jointvel name="finger_1_vel" joint="finger_1_base_joint" />
    <tendonpos name="finger_1_flexor_len" tendon="finger_1_flexor" />
  </sensor>
  <contact>
    <pair name="gripper_object_finger_0_seg_2_geom_egg_geom" geom1="finger_0_seg_2_geom" geom2="egg_geom" condim="3"/>
    <pair name="gripper_object_finger_1_seg_3_geom_egg_geom" geom1="finger_1_seg_3_geom" geom2="egg_geom" condim="3"/>
    <pair name="gripper_object_finger_0_seg_0_egg_geom" geom1="finger_0_seg_0" geom2="egg_geom" condim="3"/>
    <pair name="gripper_object_finger_1_seg_0_egg_geom" geom1="finger_1_seg_0" geom2="egg_geom" condim="3"/>
    <pair name="gripper_object_palm_geom_egg_geom" geom1="palm_geom" geom2="egg_geom" condim="3"/>
    <pair name="gripper_object_finger_1_seg_2_geom_egg_geom" geom1="finger_1_seg_2_geom" geom2="egg_geom" condim="3"/>
    <pair name="gripper_object_finger_0_seg_1_geom_egg_geom" geom1="finger_0_seg_1_geom" geom2="egg_geom" condim="3"/>
    <pair name="gripper_object_finger_0_seg_3_geom_egg_geom" geom1="finger_0_seg_3_geom" geom2="egg_geom" condim="3"/>
    <pair name="gripper_object_finger_1_seg_1_geom_egg_geom" geom1="finger_1_seg_1_geom" geom2="egg_geom" condim="3"/>
  </contact>
</mujoco>