<?xml version="1.0"?>
<robot name="Wrap_Gripper_-_Wet_-_Soft_Objects">

    <link name="palm_link">
        <visual>
            <geometry>
                <cylinder radius="0.0300" length="0.0100"/>
            </geometry>
        </visual>
        <collision>
            <geometry>
                <cylinder radius="0.0300" length="0.0100"/>
            </geometry>
        </collision>
    </link>

    
    <link name="finger_0_link">
        <visual>
            <geometry>
                <cylinder radius="0.0067" length="0.0900"/>
            </geometry>
            <origin xyz="0 0 0.0450"/>
        </visual>
        <collision>
            <geometry>
                <cylinder radius="0.0067" length="0.0900"/>
            </geometry>
            <origin xyz="0 0 0.0450"/>
        </collision>
    </link>

    <joint name="finger_0_joint" type="revolute">
        <parent link="palm_link"/>
        <child link="finger_0_link"/>
        <origin xyz="0.0300 0.0000 0.0100" rpy="0 0 0.0000"/>
        <axis xyz="0 1 0"/>
        <limit lower="-1.57" upper="1.57" effort="10" velocity="1"/>
    </joint>

    <link name="finger_1_link">
        <visual>
            <geometry>
                <cylinder radius="0.0067" length="0.0900"/>
            </geometry>
            <origin xyz="0 0 0.0450"/>
        </visual>
        <collision>
            <geometry>
                <cylinder radius="0.0067" length="0.0900"/>
            </geometry>
            <origin xyz="0 0 0.0450"/>
        </collision>
    </link>

    <joint name="finger_1_joint" type="revolute">
        <parent link="palm_link"/>
        <child link="finger_1_link"/>
        <origin xyz="-0.0150 0.0260 0.0100" rpy="0 0 2.0944"/>
        <axis xyz="0 1 0"/>
        <limit lower="-1.57" upper="1.57" effort="10" velocity="1"/>
    </joint>

    <link name="finger_2_link">
        <visual>
            <geometry>
                <cylinder radius="0.0067" length="0.0900"/>
            </geometry>
            <origin xyz="0 0 0.0450"/>
        </visual>
        <collision>
            <geometry>
                <cylinder radius="0.0067" length="0.0900"/>
            </geometry>
            <origin xyz="0 0 0.0450"/>
        </collision>
    </link>

    <joint name="finger_2_joint" type="revolute">
        <parent link="palm_link"/>
        <child link="finger_2_link"/>
        <origin xyz="-0.0150 -0.0260 0.0100" rpy="0 0 4.1888"/>
        <axis xyz="0 1 0"/>
        <limit lower="-1.57" upper="1.57" effort="10" velocity="1"/>
    </joint>

</robot>
